Workbook
Name basefx: FX!#REF!
Name dobjfx: FX!#REF!
Name enemyfx: FX!#REF!
Name evefx: FX!#REF!
Name expfx: FX!#REF!
Name feetfx: FX!#REF!
Name genfx: FX!#REF!
Name mitemsfx: FX!#REF!
Name mmpets: FX!#REF!
Name npcfx: FX!#REF!
Name powerfx: FX!#REF!
Name venemyfx: FX!#REF!
Name vgenfx: FX!#REF!
Name vitemsfx: FX!#REF!
Name vpowerfx: FX!#REF!
Name vweapfx: FX!#REF!
Name vworldfx: FX!#REF!
Name weapfx: FX!#REF!
Name worldfx: FX!#REF!

Sheet Power_Spreadsheet
A1: Class | B1: PowerSet | C1: Power | D1: FX | E1: FXLookupKey
A2: A. Soldier | B2: Arachnos Soldier | C2: Bayonet | D2: =VLOOKUP(E2 & "*",FX!C:D,2,FALSE) -> #N/A | E2: =SUBSTITUTE(C2," ","") -> Bayonet
A3: A. Soldier | B3: Arachnos Soldier | C3: Burst | D3: =VLOOKUP(E3 & "*",FX!C:D,2,FALSE) -> V_COV/ENEMYPOWERS/VANGUARD/RIFLE/BURST.FX | E3: =SUBSTITUTE(C3," ","") -> Burst
A4: A. Soldier | B4: Arachnos Soldier | C4: Frag Grenade | D4: =VLOOKUP(E4 & "*",FX!C:D,2,FALSE) -> WEAPONFX/FRAGGRENADETHROW.FX | E4: =SUBSTITUTE(C4," ","") -> FragGrenade
A5: A. Soldier | B5: Arachnos Soldier | C5: Heavy Burst | D5: =VLOOKUP(E5 & "*",FX!C:D,2,FALSE) -> #N/A | E5: =SUBSTITUTE(C5," ","") -> HeavyBurst
A6: A. Soldier | B6: Arachnos Soldier | C6: Pummel | D6: =VLOOKUP(E6 & "*",FX!C:D,2,FALSE) -> #N/A | E6: =SUBSTITUTE(C6," ","") -> Pummel
A7: A. Soldier | B7: Arachnos Soldier | C7: Single Shot | D7: =VLOOKUP(E7 & "*",FX!C:D,2,FALSE) -> #N/A | E7: =SUBSTITUTE(C7," ","") -> SingleShot
A8: A. Soldier | B8: Arachnos Soldier | C8: Venom Grenade | D8: =VLOOKUP(E8 & "*",FX!C:D,2,FALSE) -> #N/A | E8: =SUBSTITUTE(C8," ","") -> VenomGrenade
A9: A. Soldier | B9: Arachnos Soldier | C9: Wide Area Web Grenade | D9: =VLOOKUP(E9 & "*",FX!C:D,2,FALSE) -> #N/A | E9: =SUBSTITUTE(C9," ","") -> WideAreaWebGrenade
A10: A. Soldier | B10: Bane Spider Soldier | C10: Bash | D10: =VLOOKUP(E10 & "*",FX!C:D,2,FALSE) -> #N/A | E10: =SUBSTITUTE(C10," ","") -> Bash
A11: A. Soldier | B11: Bane Spider Soldier | C11: Build Up | D11: =VLOOKUP(E11 & "*",FX!C:D,2,FALSE) -> POWERS/BUILDUP_ARCHERY_AIM.FX | E11: =SUBSTITUTE(C11," ","") -> BuildUp
A12: A. Soldier | B12: Bane Spider Soldier | C12: Crowd Control | D12: =VLOOKUP(E12 & "*",FX!C:D,2,FALSE) -> #N/A | E12: =SUBSTITUTE(C12," ","") -> CrowdControl
A13: A. Soldier | B13: Bane Spider Soldier | C13: Mace Beam | D13: =VLOOKUP(E13 & "*",FX!C:D,2,FALSE) -> #N/A | E13: =SUBSTITUTE(C13," ","") -> MaceBeam
... A759: Brute | B759: Invulnerability | C759: Dull Pain | D759: =VLOOKUP(E759 & "*",FX!C:D,2,FALSE) -> POWERS/COSMICPOWERS/PEACEBRINGER/DULLPAIN/DULLPAIN.FX | E759: =SUBSTITUTE(C759," ","") -> DullPain
A760: Brute | B760: Invulnerability | C760: Invincibility | D760: =VLOOKUP(E760 & "*",FX!C:D,2,FALSE) -> POWERS/INVULNERABILITY/INVINCIBILITY.FX | E760: =SUBSTITUTE(C760," ","") -> Invincibility | H760: Chil
A761: Brute | B761: Invulnerability | C761: Resist Elements | D761: =VLOOKUP(E761 & "*",FX!C:D,2,FALSE) -> #N/A | E761: =SUBSTITUTE(C761," ","") -> ResistElements
A762: Brute | B762: Invulnerability | C762: Resist Energies | D762: =VLOOKUP(E762 & "*",FX!C:D,2,FALSE) -> #N/A | E762: =SUBSTITUTE(C762," ","") -> ResistEnergies
A763: Brute | B763: Invulnerability | C763: Resist Physical Damage | D763: =VLOOKUP(E763 & "*",FX!C:D,2,FALSE) -> #N/A | E763: =SUBSTITUTE(C763," ","") -> ResistPhysicalDamage
A764: Brute | B764: Invulnerability | C764: Temp Invulnerability | D764: =VLOOKUP(E764 & "*",FX!C:D,2,FALSE) -> #N/A | E764: =SUBSTITUTE(C764," ","") -> TempInvulnerability
A765: Brute | B765: Invulnerability | C765: Tough Hide | D765: =VLOOKUP(E765 & "*",FX!C:D,2,FALSE) -> #N/A | E765: =SUBSTITUTE(C765," ","") -> ToughHide
A766: Brute | B766: Invulnerability | C766: Unstoppable | D766: =VLOOKUP(E766 & "*",FX!C:D,2,FALSE) -> #N/A | E766: =SUBSTITUTE(C766," ","") -> Unstoppable
A767: Brute | B767: Invulnerability | C767: Unyielding | D767: =VLOOKUP(E767 & "*",FX!C:D,2,FALSE) -> POWERS/INVULNERABILITY/UNYIELDINGSTANCE.FX | E767: =SUBSTITUTE(C767," ","") -> Unyielding
A768: Brute | B768: Katana | C768: Build Up | D768: =VLOOKUP(E768 & "*",FX!C:D,2,FALSE) -> POWERS/BUILDUP_ARCHERY_AIM.FX | E768: =SUBSTITUTE(C768," ","") -> BuildUp
A769: Brute | B769: Katana | C769: Divine Avalanche | D769: =VLOOKUP(E769 & "*",FX!C:D,2,FALSE) -> #N/A | E769: =SUBSTITUTE(C769," ","") -> DivineAvalanche
A770: Brute | B770: Katana | C770: Dragon's Roar | D770: =VLOOKUP(E770 & "*",FX!C:D,2,FALSE) -> #N/A | E770: =SUBSTITUTE(C770," ","") -> Dragon'sRoar
A771: Brute | B771: Katana | C771: Flashing Steel | D771: =VLOOKUP(E771 & "*",FX!C:D,2,FALSE) -> #N/A | E771: =SUBSTITUTE(C771," ","") -> FlashingSteel
A772: Brute | B772: Katana | C772: Gambler's Cut | D772: =VLOOKUP(E772 & "*",FX!C:D,2,FALSE) -> #N/A | E772: =SUBSTITUTE(C772," ","") -> Gambler'sCut
... A3868: Warshade | B3868: Utility Belt | C3868: Poisoned Dagger | D3868: =VLOOKUP(E3868 & "*",FX!C:D,2,FALSE) -> #N/A | E3868: =SUBSTITUTE(C3868," ","") -> PoisonedDagger

Sheet FX
A1: Group | B1: Set | C1: FXLookupKey | D1: FXPath | E1: Type
A2: BASE FX | B2: Salvage Temp Powers | C2: =SUBSTITUTE(RIGHT(D2,LEN(D2)-FIND("$",SUBSTITUTE(D2,"/","$",LEN(D2)-LEN(SUBSTITUTE(D2,"/",""))))), ".FX","") -> BASETEMPPOWERDEBTPROTECTIONCONTINUING | D2: V_COV/BASEFX/SALVAGETEMPPOWERS/BASETEMPPOWERDEBTPROTECTIONCONTINUING.FX | E2: Maintained
A3: BASE FX | B3: Salvage Temp Powers | C3: =SUBSTITUTE(RIGHT(D3,LEN(D3)-FIND("$",SUBSTITUTE(D3,"/","$",LEN(D3)-LEN(SUBSTITUTE(D3,"/",""))))), ".FX","") -> BASETEMPPOWERFLIGHTCONTINUING | D3: V_COV/BASEFX/SALVAGETEMPPOWERS/BASETEMPPOWERFLIGHTCONTINUING.FX | E3: Maintained
A4: BASE FX | B4: Salvage Temp Powers | C4: =SUBSTITUTE(RIGHT(D4,LEN(D4)-FIND("$",SUBSTITUTE(D4,"/","$",LEN(D4)-LEN(SUBSTITUTE(D4,"/",""))))), ".FX","") -> BASETEMPPOWERKNOCKBACKPROTECTIONCONTINUING | D4: V_COV/BASEFX/SALVAGETEMPPOWERS/BASETEMPPOWERKNOCKBACKPROTECTIONCONTINUING.FX | E4: Maintained
A5: BASE FX | B5: Salvage Temp Powers | C5: =SUBSTITUTE(RIGHT(D5,LEN(D5)-FIND("$",SUBSTITUTE(D5,"/","$",LEN(D5)-LEN(SUBSTITUTE(D5,"/",""))))), ".FX","") -> BASETEMPPOWERSTATUSPROTECTIONCONTINUING | D5: V_COV/BASEFX/SALVAGETEMPPOWERS/BASETEMPPOWERSTATUSPROTECTIONCONTINUING.FX | E5: Maintained
A6: BASE FX | B6: Salvage Temp Powers | C6: =SUBSTITUTE(RIGHT(D6,LEN(D6)-FIND("$",SUBSTITUTE(D6,"/","$",LEN(D6)-LEN(SUBSTITUTE(D6,"/",""))))), ".FX","") -> FLIGHTBOOST | D6: V_COV/BASEFX/SALVAGETEMPPOWERS/FLIGHTBOOST.FX | E6: Maintained
A7: DESTRUCTIBLE OBJECTS | B7: Destructible Objects | C7: =SUBSTITUTE(RIGHT(D7,LEN(D7)-FIND("$",SUBSTITUTE(D7,"/","$",LEN(D7)-LEN(SUBSTITUTE(D7,"/",""))))), ".FX","") -> COT_ACTIVATION_RUNE | D7: V_COV/DESTRUCTIBLE_OBJECTS/COT_DESTRUCTIBLE_RUNE/COT_ACTIVATION_RUNE.FX | E7: Maintained
A8: DESTRUCTIBLE OBJECTS | B8: Destructible Objects | C8: =SUBSTITUTE(RIGHT(D8,LEN(D8)-FIND("$",SUBSTITUTE(D8,"/","$",LEN(D8)-LEN(SUBSTITUTE(D8,"/",""))))), ".FX","") -> COT_DESTRUCTIBLE_RUNE | D8: V_COV/DESTRUCTIBLE_OBJECTS/COT_DESTRUCTIBLE_RUNE/COT_DESTRUCTIBLE_RUNE.FX | E8: Maintained
A9: ENEMY FX & ENEMY POWERS - CoV Grouping | B9: Arachnos | C9: =SUBSTITUTE(RIGHT(D9,LEN(D9)-FIND("$",SUBSTITUTE(D9,"/","$",LEN(D9)-LEN(SUBSTITUTE(D9,"/",""))))), ".FX","") -> ARACHNOBOT_EB_EMP | D9: V_COV/ENEMYPOWERS/ARACHNOS/ARACHNOBOT_EB_EMP.FX | E9: OneShot
A10: ENEMY FX & ENEMY POWERS - CoV Grouping | B10: Arachnos | C10: =SUBSTITUTE(RIGHT(D10,LEN(D10)-FIND("$",SUBSTITUTE(D10,"/","$",LEN(D10)-LEN(SUBSTITUTE(D10,"/",""))))), ".FX","") -> ARACHNOID_VENOMBARB | D10: V_COV/ENEMYPOWERS/ARACHNOS/ARACHNOID_VENOMBARB.FX | E10: OneShot
A11: ENEMY FX & ENEMY POWERS - CoV Grouping | B11: Arachnos | C11: =SUBSTITUTE(RIGHT(D11,LEN(D11)-FIND("$",SUBSTITUTE(D11,"/","$",LEN(D11)-LEN(SUBSTITUTE(D11,"/",""))))), ".FX","") -> ARACHNOID_VENOMBARBHIT | D11: V_COV/ENEMYPOWERS/ARACHNOS/ARACHNOID_VENOMBARBHIT.FX | E11: OneShot
A12: ENEMY FX & ENEMY POWERS - CoV Grouping | B12: Arachnos | C12: =SUBSTITUTE(RIGHT(D12,LEN(D12)-FIND("$",SUBSTITUTE(D12,"/","$",LEN(D12)-LEN(SUBSTITUTE(D12,"/",""))))), ".FX","") -> ARACHNOID_WEBCOCOONSPITTER | D12: V_COV/ENEMYPOWERS/ARACHNOS/ARACHNOID_WEBCOCOONSPITTER.FX | E12: OneShot
A13: ENEMY FX & ENEMY POWERS - CoV Grouping | B13: Arachnos | C13: =SUBSTITUTE(RIGHT(D13,LEN(D13)-FIND("$",SUBSTITUTE(D13,"/","$",LEN(D13)-LEN(SUBSTITUTE(D13,"/",""))))), ".FX","") -> ARACHNOID_WEBSPITTER | D13: V_COV/ENEMYPOWERS/ARACHNOS/ARACHNOID_WEBSPITTER.FX | E13: OneShot
... A628: EXPLOSIONS | B628: Explosions | C628: =SUBSTITUTE(RIGHT(D628,LEN(D628)-FIND("$",SUBSTITUTE(D628,"/","$",LEN(D628)-LEN(SUBSTITUTE(D628,"/",""))))), ".FX","") -> XMASCONFETTIEXPLOSION | D628: EXPLOSIONS/CONFETTI/XMASCONFETTIEXPLOSION.FX | E628: Maintained
A629: EXPLOSIONS | B629: EXPLOSIONS | C629: =SUBSTITUTE(RIGHT(D629,LEN(D629)-FIND("$",SUBSTITUTE(D629,"/","$",LEN(D629)-LEN(SUBSTITUTE(D629,"/",""))))), ".FX","") -> #VALUE!
A630: EXPLOSIONS | B630: EXPLOSIONS | C630: =SUBSTITUTE(RIGHT(D630,LEN(D630)-FIND("$",SUBSTITUTE(D630,"/","$",LEN(D630)-LEN(SUBSTITUTE(D630,"/",""))))), ".FX","") -> #VALUE!
A631: FEET | B631: Feet | C631: =SUBSTITUTE(RIGHT(D631,LEN(D631)-FIND("$",SUBSTITUTE(D631,"/","$",LEN(D631)-LEN(SUBSTITUTE(D631,"/",""))))), ".FX","") -> DEACTIVATE | D631: FEET/DEACTIVATE.FX | E631: OneShot
A632: FEET | B632: FEET | C632: =SUBSTITUTE(RIGHT(D632,LEN(D632)-FIND("$",SUBSTITUTE(D632,"/","$",LEN(D632)-LEN(SUBSTITUTE(D632,"/",""))))), ".FX","") -> #VALUE!
A633: FEET | B633: FEET | C633: =SUBSTITUTE(RIGHT(D633,LEN(D633)-FIND("$",SUBSTITUTE(D633,"/","$",LEN(D633)-LEN(SUBSTITUTE(D633,"/",""))))), ".FX","") -> #VALUE!
A634: GENERIC FX - CoV Grouping | B634: Generic, Continuing | C634: =SUBSTITUTE(RIGHT(D634,LEN(D634)-FIND("$",SUBSTITUTE(D634,"/","$",LEN(D634)-LEN(SUBSTITUTE(D634,"/",""))))), ".FX","") -> FIRECONTINUING | D634: V_COV/GENERICPOWERCONTINUINGFX/FIRECONTINUING.FX | E634: Maintained
A635: GENERIC FX - CoV Grouping | B635: Generic, Continuing | C635: =SUBSTITUTE(RIGHT(D635,LEN(D635)-FIND("$",SUBSTITUTE(D635,"/","$",LEN(D635)-LEN(SUBSTITUTE(D635,"/",""))))), ".FX","") -> ICECONTINUING | D635: V_COV/GENERICPOWERCONTINUINGFX/ICECONTINUING.FX | E635: Maintained
A636: GENERIC FX - CoV Grouping | B636: Generic, Continuing | C636: =SUBSTITUTE(RIGHT(D636,LEN(D636)-FIND("$",SUBSTITUTE(D636,"/","$",LEN(D636)-LEN(SUBSTITUTE(D636,"/",""))))), ".FX","") -> PLASMACONTINUING | D636: V_COV/GENERICPOWERCONTINUINGFX/PLASMACONTINUING.FX | E636: Maintained
A637: GENERIC FX - Original (CoH) Grouping | B637: Generic | C637: =SUBSTITUTE(RIGHT(D637,LEN(D637)-FIND("$",SUBSTITUTE(D637,"/","$",LEN(D637)-LEN(SUBSTITUTE(D637,"/",""))))), ".FX","") -> BAGOFMONEY | D637: GENERIC/BAGOFMONEY/BAGOFMONEY.FX | E637: Maintained
A638: GENERIC FX - Original (CoH) Grouping | B638: Generic | C638: =SUBSTITUTE(RIGHT(D638,LEN(D638)-FIND("$",SUBSTITUTE(D638,"/","$",LEN(D638)-LEN(SUBSTITUTE(D638,"/",""))))), ".FX","") -> FX_GOBLIN_FLY | D638: GENERIC/FX_GOBLIN_FLY.FX | E638: Both
A639: GENERIC FX - Original (CoH) Grouping | B639: Generic | C639: =SUBSTITUTE(RIGHT(D639,LEN(D639)-FIND("$",SUBSTITUTE(D639,"/","$",LEN(D639)-LEN(SUBSTITUTE(D639,"/",""))))), ".FX","") -> FX_GOBLIN_SMOTHER | D639: GENERIC/FX_GOBLIN_SMOTHER.FX | E639: Maintained
A640: GENERIC FX - Original (CoH) Grouping | B640: Generic | C640: =SUBSTITUTE(RIGHT(D640,LEN(D640)-FIND("$",SUBSTITUTE(D640,"/","$",LEN(D640)-LEN(SUBSTITUTE(D640,"/",""))))), ".FX","") -> FX_HEAD | D640: GENERIC/FX_HEAD.FX | E640: Maintained
A641: GENERIC FX - Original (CoH) Grouping | B641: Generic | C641: =SUBSTITUTE(RIGHT(D641,LEN(D641)-FIND("$",SUBSTITUTE(D641,"/","$",LEN(D641)-LEN(SUBSTITUTE(D641,"/",""))))), ".FX","") -> FX_ROOT_TOSS | D641: GENERIC/FX_ROOT_TOSS.FX | E641: OneShot
A642: GENERIC FX - Original (CoH) Grouping | B642: Generic | C642: =SUBSTITUTE(RIGHT(D642,LEN(D642)-FIND("$",SUBSTITUTE(D642,"/","$",LEN(D642)-LEN(SUBSTITUTE(D642,"/",""))))), ".FX","") -> FX_STUMP_TOSS | D642: GENERIC/FX_STUMP_TOSS.FX | E642: OneShot
A643: GENERIC FX - Original (CoH) Grouping | B643: Generic | C643: =SUBSTITUTE(RIGHT(D643,LEN(D643)-FIND("$",SUBSTITUTE(D643,"/","$",LEN(D643)-LEN(SUBSTITUTE(D643,"/",""))))), ".FX","") -> IMDESTRUCTIBLE | D643: GENERIC/IMDESTRUCTIBLE/IMDESTRUCTIBLE.FX | E643: Maintained
A644: GENERIC FX - Original (CoH) Grouping | B644: Generic | C644: =SUBSTITUTE(RIGHT(D644,LEN(D644)-FIND("$",SUBSTITUTE(D644,"/","$",LEN(D644)-LEN(SUBSTITUTE(D644,"/",""))))), ".FX","") -> LEVELUP1-10 | D644: GENERIC/LEVELUP1-10.FX | E644: OneShot
A645: GENERIC FX - Original (CoH) Grouping | B645: Generic | C645: =SUBSTITUTE(RIGHT(D645,LEN(D645)-FIND("$",SUBSTITUTE(D645,"/","$",LEN(D645)-LEN(SUBSTITUTE(D645,"/",""))))), ".FX","") -> LEVELUP11-20 | D645: GENERIC/LEVELUP11-20.FX | E645: OneShot
... A654: GENERIC FX - Original (CoH) Grouping | B654: Generic | C654: =SUBSTITUTE(RIGHT(D654,LEN(D654)-FIND("$",SUBSTITUTE(D654,"/","$",LEN(D654)-LEN(SUBSTITUTE(D654,"/",""))))), ".FX","") -> WRISTBAND_ACTIVATION_QUICK | D654: GENERIC/WRISTBAND_ACTIVATION_QUICK.FX | E654: OneShot
A655: GENERIC FX - Original (CoH) Grouping | B655: GENERIC FX - Original (CoH) Grouping | C655: =SUBSTITUTE(RIGHT(D655,LEN(D655)-FIND("$",SUBSTITUTE(D655,"/","$",LEN(D655)-LEN(SUBSTITUTE(D655,"/",""))))), ".FX","") -> #VALUE!
A656: GENERIC FX - Original (CoH) Grouping | B656: GENERIC FX - Original (CoH) Grouping | C656: =SUBSTITUTE(RIGHT(D656,LEN(D656)-FIND("$",SUBSTITUTE(D656,"/","$",LEN(D656)-LEN(SUBSTITUTE(D656,"/",""))))), ".FX","") -> #VALUE!
A657: GENERIC FX - Original (CoH) Grouping | B657: Generic, Continuing | C657: =SUBSTITUTE(RIGHT(D657,LEN(D657)-FIND("$",SUBSTITUTE(D657,"/","$",LEN(D657)-LEN(SUBSTITUTE(D657,"/",""))))), ".FX","") -> AFRAIDCONTINUING | D657: GENERICCONTINUING/AFRAIDCONTINUING.FX | E657: Maintained
A658: GENERIC FX - Original (CoH) Grouping | B658: Generic, Continuing | C658: =SUBSTITUTE(RIGHT(D658,LEN(D658)-FIND("$",SUBSTITUTE(D658,"/","$",LEN(D658)-LEN(SUBSTITUTE(D658,"/",""))))), ".FX","") -> ARCHMESRES | D658: GENERICCONTINUING/ARCHMESRES/ARCHMESRES.FX | E658: Maintained
A659: GENERIC FX - Original (CoH) Grouping | B659: Generic, Continuing | C659: =SUBSTITUTE(RIGHT(D659,LEN(D659)-FIND("$",SUBSTITUTE(D659,"/","$",LEN(D659)-LEN(SUBSTITUTE(D659,"/",""))))), ".FX","") -> ARCHMESRESACTIVATE | D659: GENERICCONTINUING/ARCHMESRES/ARCHMESRESACTIVATE.FX | E659: OneShot
A660: GENERIC FX - Original (CoH) Grouping | B660: Generic, Continuing | C660: =SUBSTITUTE(RIGHT(D660,LEN(D660)-FIND("$",SUBSTITUTE(D660,"/","$",LEN(D660)-LEN(SUBSTITUTE(D660,"/",""))))), ".FX","") -> BUFFDAMAGECONTINUING | D660: GENERICCONTINUING/BUFFDAMAGECONTINUING.FX | E660: Maintained
A661: GENERIC FX - Original (CoH) Grouping | B661: Generic, Continuing | C661: =SUBSTITUTE(RIGHT(D661,LEN(D661)-FIND("$",SUBSTITUTE(D661,"/","$",LEN(D661)-LEN(SUBSTITUTE(D661,"/",""))))), ".FX","") -> BUFFDAMRESCONTINUING | D661: GENERICCONTINUING/DAMAGERESISTANCE/BUFFDAMRESCONTINUING.FX | E661: Maintained
A662: GENERIC FX - Original (CoH) Grouping | B662: Generic, Continuing | C662: =SUBSTITUTE(RIGHT(D662,LEN(D662)-FIND("$",SUBSTITUTE(D662,"/","$",LEN(D662)-LEN(SUBSTITUTE(D662,"/",""))))), ".FX","") -> BUFFDEF | D662: GENERICCONTINUING/BUFFDEF.FX | E662: Maintained
...
